<?xml version="1.0" encoding="UTF-8"?>
<!-- Generated by org.testng.reporters.JUnitReportReporter -->
<testsuite skipped="0" hostname="RHJ-14F-D547" name="com.scripts.creditmemo.creation.TS_NS_121_SpotOnly_Invoice_Rebill" tests="2" failures="0" timestamp="11 Mar 2020 11:46:09 GMT" time="2556.441" errors="2">
  <testcase name="ExtentReport" time="2.424" classname="com.scripts.creditmemo.creation.TS_NS_121_SpotOnly_Invoice_Rebill">
    <error type="org.openqa.selenium.WebDriverException" message="java.net.ConnectException: Failed to connect to localhost/0:0:0:0:0:0:0:1:2185
Build info: version: &#039;3.141.59&#039;, revision: &#039;e82be7d358&#039;, time: &#039;2018-11-14T08:17:03&#039;
System info: host: &#039;RHJ-14F-D547&#039;, ip: &#039;10.11.53.81&#039;, os.name: &#039;Windows 8.1&#039;, os.arch: &#039;amd64&#039;, os.version: &#039;6.3&#039;, java.version: &#039;1.8.0_131&#039;
Driver info: driver.version: RemoteWebDriver">
      <![CDATA[org.openqa.selenium.WebDriverException: java.net.ConnectException: Failed to connect to localhost/0:0:0:0:0:0:0:1:2185
Build info: version: '3.141.59', revision: 'e82be7d358', time: '2018-11-14T08:17:03'
System info: host: 'RHJ-14F-D547', ip: '10.11.53.81', os.name: 'Windows 8.1', os.arch: 'amd64', os.version: '6.3', java.version: '1.8.0_131'
Driver info: driver.version: RemoteWebDriver
at org.openqa.selenium.remote.service.DriverCommandExecutor.execute(DriverCommandExecutor.java:92)
at org.openqa.selenium.remote.RemoteWebDriver.execute(RemoteWebDriver.java:552)
at org.openqa.selenium.remote.RemoteWebDriver.execute(RemoteWebDriver.java:609)
at org.openqa.selenium.remote.RemoteWebDriver.close(RemoteWebDriver.java:442)
at com.scripts.creditmemo.creation.TS_NS_121_SpotOnly_Invoice_Rebill.ExtentReport(TS_NS_121_SpotOnly_Invoice_Rebill.java:106)
at sun.reflect.NativeMethodAccessorImpl.invoke0(Native Method)
at sun.reflect.NativeMethodAccessorImpl.invoke(Unknown Source)
at sun.reflect.DelegatingMethodAccessorImpl.invoke(Unknown Source)
at java.lang.reflect.Method.invoke(Unknown Source)
at org.testng.internal.MethodInvocationHelper.invokeMethod(MethodInvocationHelper.java:124)
at org.testng.internal.MethodInvocationHelper.invokeMethodConsideringTimeout(MethodInvocationHelper.java:59)
at org.testng.internal.Invoker.invokeConfigurationMethod(Invoker.java:455)
at org.testng.internal.Invoker.invokeConfigurations(Invoker.java:222)
at org.testng.internal.Invoker.invokeMethod(Invoker.java:643)
at org.testng.internal.Invoker.invokeTestMethod(Invoker.java:716)
at org.testng.internal.Invoker.invokeTestMethods(Invoker.java:988)
at org.testng.internal.TestMethodWorker.invokeTestMethods(TestMethodWorker.java:125)
at org.testng.internal.TestMethodWorker.run(TestMethodWorker.java:109)
at org.testng.TestRunner.privateRun(TestRunner.java:648)
at org.testng.TestRunner.run(TestRunner.java:505)
at org.testng.SuiteRunner.runTest(SuiteRunner.java:455)
at org.testng.SuiteRunner.runSequentially(SuiteRunner.java:450)
at org.testng.SuiteRunner.privateRun(SuiteRunner.java:415)
at org.testng.SuiteRunner.run(SuiteRunner.java:364)
at org.testng.SuiteRunnerWorker.runSuite(SuiteRunnerWorker.java:52)
at org.testng.SuiteRunnerWorker.run(SuiteRunnerWorker.java:84)
at org.testng.TestNG.runSuitesSequentially(TestNG.java:1208)
at org.testng.TestNG.runSuitesLocally(TestNG.java:1137)
at org.testng.TestNG.runSuites(TestNG.java:1049)
at org.testng.TestNG.run(TestNG.java:1017)
at org.testng.remote.AbstractRemoteTestNG.run(AbstractRemoteTestNG.java:132)
at org.testng.remote.RemoteTestNG.initAndRun(RemoteTestNG.java:236)
at org.testng.remote.RemoteTestNG.main(RemoteTestNG.java:81)
Caused by: java.net.ConnectException: Failed to connect to localhost/0:0:0:0:0:0:0:1:2185
at okhttp3.internal.connection.RealConnection.connectSocket(RealConnection.java:223)
at okhttp3.internal.connection.RealConnection.connect(RealConnection.java:147)
at okhttp3.internal.connection.StreamAllocation.findConnection(StreamAllocation.java:192)
at okhttp3.internal.connection.StreamAllocation.findHealthyConnection(StreamAllocation.java:121)
at okhttp3.internal.connection.StreamAllocation.newStream(StreamAllocation.java:100)
at okhttp3.internal.connection.ConnectInterceptor.intercept(ConnectInterceptor.java:42)
at okhttp3.internal.http.RealInterceptorChain.proceed(RealInterceptorChain.java:92)
at okhttp3.internal.http.RealInterceptorChain.proceed(RealInterceptorChain.java:67)
at okhttp3.internal.cache.CacheInterceptor.intercept(CacheInterceptor.java:93)
at okhttp3.internal.http.RealInterceptorChain.proceed(RealInterceptorChain.java:92)
at okhttp3.internal.http.RealInterceptorChain.proceed(RealInterceptorChain.java:67)
at okhttp3.internal.http.BridgeInterceptor.intercept(BridgeInterceptor.java:93)
at okhttp3.internal.http.RealInterceptorChain.proceed(RealInterceptorChain.java:92)
at okhttp3.internal.http.RetryAndFollowUpInterceptor.intercept(RetryAndFollowUpInterceptor.java:120)
at okhttp3.internal.http.RealInterceptorChain.proceed(RealInterceptorChain.java:92)
at okhttp3.internal.http.RealInterceptorChain.proceed(RealInterceptorChain.java:67)
at okhttp3.RealCall.getResponseWithInterceptorChain(RealCall.java:185)
at okhttp3.RealCall.execute(RealCall.java:69)
at org.openqa.selenium.remote.internal.OkHttpClient.execute(OkHttpClient.java:103)
at org.openqa.selenium.remote.HttpCommandExecutor.execute(HttpCommandExecutor.java:155)
at org.openqa.selenium.remote.service.DriverCommandExecutor.execute(DriverCommandExecutor.java:83)
... 32 more
Caused by: java.net.ConnectException: Connection refused: connect
at java.net.DualStackPlainSocketImpl.waitForConnect(Native Method)
at java.net.DualStackPlainSocketImpl.socketConnect(Unknown Source)
at java.net.AbstractPlainSocketImpl.doConnect(Unknown Source)
at java.net.AbstractPlainSocketImpl.connectToAddress(Unknown Source)
at java.net.AbstractPlainSocketImpl.connect(Unknown Source)
at java.net.PlainSocketImpl.connect(Unknown Source)
at java.net.SocksSocketImpl.connect(Unknown Source)
at java.net.Socket.connect(Unknown Source)
at okhttp3.internal.platform.Platform.connectSocket(Platform.java:124)
at okhttp3.internal.connection.RealConnection.connectSocket(RealConnection.java:221)
... 52 more
]]>
    </error>
  </testcase> <!-- ExtentReport -->
  <testcase name="TS_NS_121_SpotOnly_Invoice_Rebill" time="2554.017" classname="com.scripts.creditmemo.creation.TS_NS_121_SpotOnly_Invoice_Rebill">
    <error type="junit.framework.AssertionFailedError" message=" rebill - makecopy is not found">
      <![CDATA[junit.framework.AssertionFailedError:  rebill - makecopy is not found
at junit.framework.Assert.fail(Assert.java:47)
at junit.framework.Assert.assertTrue(Assert.java:20)
at com.framework.Generic.Verify(Generic.java:295)
at com.framework.Generic.clickButton(Generic.java:327)
at com.netsuite.common.NS_Billing_AdjustmentAndSpecialBilling.market_invoice_rebill(NS_Billing_AdjustmentAndSpecialBilling.java:3061)
at com.scripts.creditmemo.creation.TS_NS_121_SpotOnly_Invoice_Rebill.TS_NS_121_SpotOnly_Invoice_Rebill(TS_NS_121_SpotOnly_Invoice_Rebill.java:95)
at sun.reflect.NativeMethodAccessorImpl.invoke0(Native Method)
at sun.reflect.NativeMethodAccessorImpl.invoke(Unknown Source)
at sun.reflect.DelegatingMethodAccessorImpl.invoke(Unknown Source)
at java.lang.reflect.Method.invoke(Unknown Source)
at org.testng.internal.MethodInvocationHelper.invokeMethod(MethodInvocationHelper.java:124)
at org.testng.internal.Invoker.invokeMethod(Invoker.java:580)
at org.testng.internal.Invoker.invokeTestMethod(Invoker.java:716)
at org.testng.internal.Invoker.invokeTestMethods(Invoker.java:988)
at org.testng.internal.TestMethodWorker.invokeTestMethods(TestMethodWorker.java:125)
at org.testng.internal.TestMethodWorker.run(TestMethodWorker.java:109)
at org.testng.TestRunner.privateRun(TestRunner.java:648)
at org.testng.TestRunner.run(TestRunner.java:505)
at org.testng.SuiteRunner.runTest(SuiteRunner.java:455)
at org.testng.SuiteRunner.runSequentially(SuiteRunner.java:450)
at org.testng.SuiteRunner.privateRun(SuiteRunner.java:415)
at org.testng.SuiteRunner.run(SuiteRunner.java:364)
at org.testng.SuiteRunnerWorker.runSuite(SuiteRunnerWorker.java:52)
at org.testng.SuiteRunnerWorker.run(SuiteRunnerWorker.java:84)
at org.testng.TestNG.runSuitesSequentially(TestNG.java:1208)
at org.testng.TestNG.runSuitesLocally(TestNG.java:1137)
at org.testng.TestNG.runSuites(TestNG.java:1049)
at org.testng.TestNG.run(TestNG.java:1017)
at org.testng.remote.AbstractRemoteTestNG.run(AbstractRemoteTestNG.java:132)
at org.testng.remote.RemoteTestNG.initAndRun(RemoteTestNG.java:236)
at org.testng.remote.RemoteTestNG.main(RemoteTestNG.java:81)
]]>
    </error>
  </testcase> <!-- TS_NS_121_SpotOnly_Invoice_Rebill -->
</testsuite> <!-- com.scripts.creditmemo.creation.TS_NS_121_SpotOnly_Invoice_Rebill -->
